<?xml version="1.0"?>
<robot name="health_bot" xmlns:xacro="http://www.ros.org">

    <xacro:include filename="inertials.xacro" />

    <material name="white"> <color rgba="1 1 1 1" /> </material>
    <material name="blue"> <color rgba="0.2 0.2 1 1" /> </material>
    <material name="black"> <color rgba="0 0 0 1" /> </material>

    <link name="base_link"></link>

    <joint name="chassis_joint" type="fixed">
        <parent link="base_link" />
        <child link="chassis" />
        <origin xyz="-0.1 0 0" />
    </joint>

    <link name="chassis">
        <visual>
            <origin xyz="0.25 0 0.075" />
            <geometry> <box size="0.5 0.3 0.15" /> </geometry>
            <material name="white" />
        </visual>
        <collision>
            <origin xyz="0.25 0 0.075" />
            <geometry> <box size="0.5 0.3 0.15" /> </geometry>
        </collision>
        <xacro:inertial_box mass="0.5" x="0.5" y="0.3" z="0.15">
            <origin xyz="0.25 0 0.075" rpy="0 0 0" />
        </xacro:inertial_box>
    </link>

    <xacro:macro name="wheel" params="prefix y_reflect">
        <joint name="${prefix}_wheel_joint" type="continuous">
            <parent link="base_link" />
            <child link="${prefix}_wheel" />
            <origin xyz="0 ${y_reflect * 0.175} 0" rpy="-${pi/2} 0 0" />
            <axis xyz="0 0 1" />
        </joint>
        <link name="${prefix}_wheel">
            <visual>
                <geometry> <cylinder radius="0.1" length="0.04" /> </geometry>
                <material name="blue" />
            </visual>
            <collision>
                <geometry> <cylinder radius="0.1" length="0.04" /> </geometry>
            </collision>
            <xacro:inertial_cylinder mass="0.1" length="0.04" radius="0.1">
                <origin xyz="0 0 0" rpy="0 0 0" />
            </xacro:inertial_cylinder>
        </link>
    </xacro:macro>

    <xacro:wheel prefix="left" y_reflect="1" />
    <xacro:wheel prefix="right" y_reflect="-1" />

    <joint name="caster_wheel_joint" type="fixed">
        <parent link="chassis" />
        <child link="caster_wheel" />
        <origin xyz="0.4 0 0" />
    </joint>

    <link name="caster_wheel">
        <visual>
            <geometry> <sphere radius="0.05" /> </geometry>
            <material name="black" />
        </visual>
        <collision>
            <geometry> <sphere radius="0.05" /> </geometry>
        </collision>
        <xacro:inertial_sphere mass="0.1" radius="0.05">
            <origin xyz="0 0 0" rpy="0 0 0" />
        </xacro:inertial_sphere>
    </link>

    <gazebo reference="chassis"> <material>Gazebo/Orange</material> </gazebo>
    <gazebo reference="left_wheel"> <material>Gazebo/Blue</material> </gazebo>
    <gazebo reference="right_wheel"> <material>Gazebo/Blue</material> </gazebo>
    <gazebo reference="caster_wheel">
        <material>Gazebo/Black</material>
        <mu1 value="0.001" />
        <mu2 value="0.001" />
    </gazebo>

    <gazebo>
        <plugin filename="gz-sim-diff-drive-system" name="gz::sim::systems::DiffDrive">
            <left_joint>left_wheel_joint</left_joint>
            <right_joint>right_wheel_joint</right_joint>
            <wheel_separation>0.35</wheel_separation>
            <wheel_radius>0.1</wheel_radius>
            <topic>cmd_vel</topic>
            <odom_topic>odom</odom_topic>
            <frame_id>odom</frame_id>
            <child_frame_id>base_link</child_frame_id>
        </plugin>
        <plugin filename="gz-sim-joint-state-publisher-system" name="gz::sim::systems::JointStatePublisher"></plugin>
    </gazebo>
    <!-- LiDAR JOINT -->
    <joint name="laser_joint" type="fixed">
        <parent link="chassis"/>
        <child link="laser_frame"/>
        <origin xyz="0.1 0 0.175" rpy="0 0 0"/>
    </joint>

    <!-- LiDAR LINK -->
    <link name="laser_frame">
        <visual>
            <geometry>
                <cylinder radius="0.05" length="0.04"/>
            </geometry>
            <material name="black"/>
        </visual>
        <collision>
            <geometry>
                <cylinder radius="0.05" length="0.04"/>
            </geometry>
        </collision>
        <xacro:inertial_cylinder mass="0.1" length="0.04" radius="0.05">
            <origin xyz="0 0 0" rpy="0 0 0"/>
        </xacro:inertial_cylinder>
    </link>
    <gazebo reference="laser_frame">
        <material>Gazebo/Black</material>
        <sensor name="laser" type="gpu_lidar">
            <pose> 0 0 0 0 0 0 </pose>
            <visualize>true</visualize>
            <update_rate>10</update_rate>
            <lidar>
                <scan>
                    <horizontal>
                        <samples>360</samples>
                        <min_angle>-3.14</min_angle>
                        <max_angle>3.14</max_angle>
                    </horizontal>
                </scan>
                <range>
                    <min>0.3</min>
                    <max>12</max>
                </range>
            </lidar>
            <topic>scan</topic>
            <!-- <gz_frame_id>laser_frame</gz_frame_id> -->
        </sensor>
    </gazebo>
    
</robot>

